Workbook

Sheet Welcome
B2: THE ULTIMATE BUDGET PLANNER
B4: A complete system for planning, tracking & growing your money
B6: YEAR
B7: 2026
B9: WHAT'S INSIDE
B10: Dashboard | C10: Your at-a-glance yearly overview with automatic charts.
B11: Jan - Dec Tabs | C11: A full monthly budget: plan it, then track what actually happened.
B12: Transactions | C12: Log every purchase once — everything else updates itself.
B13: Annual Overview | C13: All 12 months side-by-side, so trends jump right out.
B14: Debt Payoff Tracker | C14: See exactly when each debt will hit zero.
B15: Savings Goals | C15: Turn 'someday' goals into a monthly savings number.
B17: HOW TO USE THIS PLANNER
B18: 1. Start on the Transactions tab and log your income & expenses as they happen (or all at once for the month).
B19: 2. Open the matching month tab (Jan, Feb, ...) and fill in the yellow BUDGETED column with your plan for each category.
B20: 3. The ACTUAL and VARIANCE columns fill in automatically from your Transactions log — no manual math required.
B21: 4. Check the Dashboard any time for a live picture of the whole year.
B22: 5. Use the Debt Payoff and Savings Goals tabs to plan beyond the month-to-month.
B24: COLOR KEY
C25: Yellow / gold cells = type your own numbers here
C26: White cells with a formula = calculated automatically, don't overwrite
C27: Teal band = Income section
C28: Blush band = Variable Expenses section
B31: Tip: right-click any sheet tab to duplicate it if you'd like extra copies (e.g. per bank account).

Sheet Dashboard
B2: ="YEARLY DASHBOARD — "&Welcome!$B$7 -> YEARLY DASHBOARD — 2026
B4: TOTAL INCOME (YTD) | C4: TOTAL EXPENSES (YTD) | D4: TOTAL SAVED (YTD) | E4: NET CASH FLOW (YTD)
B5: ='Annual Overview'!N50 -> 6850 | C5: ='Annual Overview'!N51 -> 1958.47 | D5: ='Annual Overview'!N52 -> 450 | E5: ='Annual Overview'!N53 -> 4441.53
B8: SAVINGS RATE (YTD) | D8: AVG MONTHLY SPEND
B9: ='Annual Overview'!N52/'Annual Overview'!N50 -> 0.065693431 | D9: ='Annual Overview'!N51/12 -> 163.20583
H11: Category | I11: YTD Total
H12: Rent / Mortgage | I12: ='Annual Overview'!N15 -> 1450
H13: Utilities | I13: ='Annual Overview'!N16 -> 165.32
H14: Insurance | I14: ='Annual Overview'!N17 -> 0
H15: Phone Bill | I15: ='Annual Overview'!N18 -> 0
H16: Internet | I16: ='Annual Overview'!N19 -> 0
H17: Subscriptions | I17: ='Annual Overview'!N20 -> 24.98
H18: Car Payment | I18: ='Annual Overview'!N21 -> 0
H19: Loan Payments | I19: ='Annual Overview'!N22 -> 0
H20: Groceries | I20: ='Annual Overview'!N26 -> 211.07
H21: Dining Out | I21: ='Annual Overview'!N27 -> 62.1
H22: Transportation / Gas | I22: ='Annual Overview'!N28 -> 45
H23: Entertainment | I23: ='Annual Overview'!N29 -> 0
H24: Shopping | I24: ='Annual Overview'!N30 -> 0
H25: Personal Care | I25: ='Annual Overview'!N31 -> 0
H26: Health / Medical | I26: ='Annual Overview'!N32 -> 0
H27: Pet Care | I27: ='Annual Overview'!N33 -> 0
H28: Childcare | I28: ='Annual Overview'!N34 -> 0
H29: Gifts & Donations | I29: ='Annual Overview'!N35 -> 0
H30: Travel | I30: ='Annual Overview'!N36 -> 0
H31: Miscellaneous | I31: ='Annual Overview'!N37 -> 0

Sheet Jan
A1: ="JANUARY"&" "&Welcome!$B$7&" BUDGET" -> JANUARY 2026 BUDGET
A2: Plan it in BUDGETED, then let ACTUAL fill in from your Transactions log.
A4: CATEGORY | B4: BUDGETED | C4: ACTUAL | D4: VARIANCE
A5: INCOME
A6: Salary | B6: 6400 | C6: =SUMIFS(Transactions!$E$4:$E$400,Transactions!$C$4:$C$400,$A6,Transactions!$F$4:$F$400,1) -> 6400 | D6: =C6-B6 -> 0
A7: Freelance / Side Hustle | B7: 400 | C7: =SUMIFS(Transactions!$E$4:$E$400,Transactions!$C$4:$C$400,$A7,Transactions!$F$4:$F$400,1) -> 450 | D7: =C7-B7 -> 50
A8: Bonus | B8: 0 | C8: =SUMIFS(Transactions!$E$4:$E$400,Transactions!$C$4:$C$400,$A8,Transactions!$F$4:$F$400,1) -> 0 | D8: =C8-B8 -> 0
A9: Investment Income | B9: 0 | C9: =SUMIFS(Transactions!$E$4:$E$400,Transactions!$C$4:$C$400,$A9,Transactions!$F$4:$F$400,1) -> 0 | D9: =C9-B9 -> 0
A10: Gifts Received | B10: 0 | C10: =SUMIFS(Transactions!$E$4:$E$400,Transactions!$C$4:$C$400,$A10,Transactions!$F$4:$F$400,1) -> 0 | D10: =C10-B10 -> 0
A11: Other Income | B11: 0 | C11: =SUMIFS(Transactions!$E$4:$E$400,Transactions!$C$4:$C$400,$A11,Transactions!$F$4:$F$400,1) -> 0 | D11: =C11-B11 -> 0
A12: Total Income | B12: =SUM(B6:B11) -> 6800 | C12: =SUM(C6:C11) -> 6850 | D12: =SUM(D6:D11) -> 50
A14: FIXED EXPENSES
A15: Rent / Mortgage | B15: 1450 | C15: =SUMIFS(Transactions!$E$4:$E$400,Transactions!$C$4:$C$400,$A15,Transactions!$F$4:$F$400,1) -> 1450 | D15: =C15-B15 -> 0
A16: Utilities | B16: 180 | C16: =SUMIFS(Transactions!$E$4:$E$400,Transactions!$C$4:$C$400,$A16,Transactions!$F$4:$F$400,1) -> 165.32 | D16: =C16-B16 -> -14.68
A17: Insurance | B17: 120 | C17: =SUMIFS(Transactions!$E$4:$E$400,Transactions!$C$4:$C$400,$A17,Transactions!$F$4:$F$400,1) -> 0 | D17: =C17-B17 -> -120
A18: Phone Bill | B18: 65 | C18: =SUMIFS(Transactions!$E$4:$E$400,Transactions!$C$4:$C$400,$A18,Transactions!$F$4:$F$400,1) -> 0 | D18: =C18-B18 -> -65
A19: Internet | B19: 60 | C19: =SUMIFS(Transactions!$E$4:$E$400,Transactions!$C$4:$C$400,$A19,Transactions!$F$4:$F$400,1) -> 0 | D19: =C19-B19 -> -60
A20: Subscriptions | B20: 35 | C20: =SUMIFS(Transactions!$E$4:$E$400,Transactions!$C$4:$C$400,$A20,Transactions!$F$4:$F$400,1) -> 24.98 | D20: =C20-B20 -> -10.02
A21: Car Payment | B21: 320 | C21: =SUMIFS(Transactions!$E$4:$E$400,Transactions!$C$4:$C$400,$A21,Transactions!$F$4:$F$400,1) -> 0 | D21: =C21-B21 -> -320
A22: Loan Payments | B22: 150 | C22: =SUMIFS(Transactions!$E$4:$E$400,Transactions!$C$4:$C$400,$A22,Transactions!$F$4:$F$400,1) -> 0 | D22: =C22-B22 -> -150
A23: Total Fixed Expenses | B23: =SUM(B15:B22) -> 2380 | C23: =SUM(C15:C22) -> 1640.3 | D23: =SUM(D15:D22) -> -739.7
A25: VARIABLE EXPENSES
A26: Groceries | B26: 450 | C26: =SUMIFS(Transactions!$E$4:$E$400,Transactions!$C$4:$C$400,$A26,Transactions!$F$4:$F$400,1) -> 211.07 | D26: =C26-B26 -> -238.93
A27: Dining Out | B27: 150 | C27: =SUMIFS(Transactions!$E$4:$E$400,Transactions!$C$4:$C$400,$A27,Transactions!$F$4:$F$400,1) -> 62.1 | D27: =C27-B27 -> -87.9
A28: Transportation / Gas | B28: 120 | C28: =SUMIFS(Transactions!$E$4:$E$400,Transactions!$C$4:$C$400,$A28,Transactions!$F$4:$F$400,1) -> 45 | D28: =C28-B28 -> -75
A29: Entertainment | B29: 80 | C29: =SUMIFS(Transactions!$E$4:$E$400,Transactions!$C$4:$C$400,$A29,Transactions!$F$4:$F$400,1) -> 0 | D29: =C29-B29 -> -80
A30: Shopping | B30: 100 | C30: =SUMIFS(Transactions!$E$4:$E$400,Transactions!$C$4:$C$400,$A30,Transactions!$F$4:$F$400,1) -> 0 | D30: =C30-B30 -> -100
A31: Personal Care | B31: 50 | C31: =SUMIFS(Transactions!$E$4:$E$400,Transactions!$C$4:$C$400,$A31,Transactions!$F$4:$F$400,1) -> 0 | D31: =C31-B31 -> -50
A32: Health / Medical | B32: 60 | C32: =SUMIFS(Transactions!$E$4:$E$400,Transactions!$C$4:$C$400,$A32,Transactions!$F$4:$F$400,1) -> 0 | D32: =C32-B32 -> -60
A33: Pet Care | B33: 40 | C33: =SUMIFS(Transactions!$E$4:$E$400,Transactions!$C$4:$C$400,$A33,Transactions!$F$4:$F$400,1) -> 0 | D33: =C33-B33 -> -40
A34: Childcare | B34: 0 | C34: =SUMIFS(Transactions!$E$4:$E$400,Transactions!$C$4:$C$400,$A34,Transactions!$F$4:$F$400,1) -> 0 | D34: =C34-B34 -> 0
A35: Gifts & Donations | B35: 40 | C35: =SUMIFS(Transactions!$E$4:$E$400,Transactions!$C$4:$C$400,$A35,Transactions!$F$4:$F$400,1) -> 0 | D35: =C35-B35 -> -40
A36: Travel | B36: 0 | C36: =SUMIFS(Transactions!$E$4:$E$400,Transactions!$C$4:$C$400,$A36,Transactions!$F$4:$F$400,1) -> 0 | D36: =C36-B36 -> 0
A37: Miscellaneous | B37: 50 | C37: =SUMIFS(Transactions!$E$4:$E$400,Transactions!$C$4:$C$400,$A37,Transactions!$F$4:$F$400,1) -> 0 | D37: =C37-B37 -> -50
A38: Total Variable Expenses | B38: =SUM(B26:B37) -> 1140 | C38: =SUM(C26:C37) -> 318.17 | D38: =SUM(D26:D37) -> -821.83
A40: SAVINGS & DEBT
A41: Emergency Fund | B41: 300 | C41: =SUMIFS(Transactions!$E$4:$E$400,Transactions!$C$4:$C$400,$A41,Transactions!$F$4:$F$400,1) -> 300 | D41: =C41-B41 -> 0
A42: Retirement Savings | B42: 200 | C42: =SUMIFS(Transactions!$E$4:$E$400,Transactions!$C$4:$C$400,$A42,Transactions!$F$4:$F$400,1) -> 0 | D42: =C42-B42 -> -200
A43: Investment Contributions | B43: 0 | C43: =SUMIFS(Transactions!$E$4:$E$400,Transactions!$C$4:$C$400,$A43,Transactions!$F$4:$F$400,1) -> 0 | D43: =C43-B43 -> 0
A44: Debt Payoff | B44: 150 | C44: =SUMIFS(Transactions!$E$4:$E$400,Transactions!$C$4:$C$400,$A44,Transactions!$F$4:$F$400,1) -> 150 | D44: =C44-B44 -> 0
...

Sheet Feb
A1: ="FEBRUARY"&" "&Welcome!$B$7&" BUDGET" -> FEBRUARY 2026 BUDGET
A2: Plan it in BUDGETED, then let ACTUAL fill in from your Transactions log.
A4: CATEGORY | B4: BUDGETED | C4: ACTUAL | D4: VARIANCE
A5: INCOME
A6: Salary | B6: 0 | C6: =SUMIFS(Transactions!$E$4:$E$400,Transactions!$C$4:$C$400,$A6,Transactions!$F$4:$F$400,2) -> 0 | D6: =C6-B6 -> 0
A7: Freelance / Side Hustle | B7: 0 | C7: =SUMIFS(Transactions!$E$4:$E$400,Transactions!$C$4:$C$400,$A7,Transactions!$F$4:$F$400,2) -> 0 | D7: =C7-B7 -> 0
A8: Bonus | B8: 0 | C8: =SUMIFS(Transactions!$E$4:$E$400,Transactions!$C$4:$C$400,$A8,Transactions!$F$4:$F$400,2) -> 0 | D8: =C8-B8 -> 0
A9: Investment Income | B9: 0 | C9: =SUMIFS(Transactions!$E$4:$E$400,Transactions!$C$4:$C$400,$A9,Transactions!$F$4:$F$400,2) -> 0 | D9: =C9-B9 -> 0
A10: Gifts Received | B10: 0 | C10: =SUMIFS(Transactions!$E$4:$E$400,Transactions!$C$4:$C$400,$A10,Transactions!$F$4:$F$400,2) -> 0 | D10: =C10-B10 -> 0
A11: Other Income | B11: 0 | C11: =SUMIFS(Transactions!$E$4:$E$400,Transactions!$C$4:$C$400,$A11,Transactions!$F$4:$F$400,2) -> 0 | D11: =C11-B11 -> 0
A12: Total Income | B12: =SUM(B6:B11) -> 0 | C12: =SUM(C6:C11) -> 0 | D12: =SUM(D6:D11) -> 0
A14: FIXED EXPENSES
A15: Rent / Mortgage | B15: 0 | C15: =SUMIFS(Transactions!$E$4:$E$400,Transactions!$C$4:$C$400,$A15,Transactions!$F$4:$F$400,2) -> 0 | D15: =C15-B15 -> 0
A16: Utilities | B16: 0 | C16: =SUMIFS(Transactions!$E$4:$E$400,Transactions!$C$4:$C$400,$A16,Transactions!$F$4:$F$400,2) -> 0 | D16: =C16-B16 -> 0
A17: Insurance | B17: 0 | C17: =SUMIFS(Transactions!$E$4:$E$400,Transactions!$C$4:$C$400,$A17,Transactions!$F$4:$F$400,2) -> 0 | D17: =C17-B17 -> 0
A18: Phone Bill | B18: 0 | C18: =SUMIFS(Transactions!$E$4:$E$400,Transactions!$C$4:$C$400,$A18,Transactions!$F$4:$F$400,2) -> 0 | D18: =C18-B18 -> 0
A19: Internet | B19: 0 | C19: =SUMIFS(Transactions!$E$4:$E$400,Transactions!$C$4:$C$400,$A19,Transactions!$F$4:$F$400,2) -> 0 | D19: =C19-B19 -> 0
A20: Subscriptions | B20: 0 | C20: =SUMIFS(Transactions!$E$4:$E$400,Transactions!$C$4:$C$400,$A20,Transactions!$F$4:$F$400,2) -> 0 | D20: =C20-B20 -> 0
A21: Car Payment | B21: 0 | C21: =SUMIFS(Transactions!$E$4:$E$400,Transactions!$C$4:$C$400,$A21,Transactions!$F$4:$F$400,2) -> 0 | D21: =C21-B21 -> 0
A22: Loan Payments | B22: 0 | C22: =SUMIFS(Transactions!$E$4:$E$400,Transactions!$C$4:$C$400,$A22,Transactions!$F$4:$F$400,2) -> 0 | D22: =C22-B22 -> 0
A23: Total Fixed Expenses | B23: =SUM(B15:B22) -> 0 | C23: =SUM(C15:C22) -> 0 | D23: =SUM(D15:D22) -> 0
A25: VARIABLE EXPENSES
A26: Groceries | B26: 0 | C26: =SUMIFS(Transactions!$E$4:$E$400,Transactions!$C$4:$C$400,$A26,Transactions!$F$4:$F$400,2) -> 0 | D26: =C26-B26 -> 0
A27: Dining Out | B27: 0 | C27: =SUMIFS(Transactions!$E$4:$E$400,Transactions!$C$4:$C$400,$A27,Transactions!$F$4:$F$400,2) -> 0 | D27: =C27-B27 -> 0
A28: Transportation / Gas | B28: 0 | C28: =SUMIFS(Transactions!$E$4:$E$400,Transactions!$C$4:$C$400,$A28,Transactions!$F$4:$F$400,2) -> 0 | D28: =C28-B28 -> 0
A29: Entertainment | B29: 0 | C29: =SUMIFS(Transactions!$E$4:$E$400,Transactions!$C$4:$C$400,$A29,Transactions!$F$4:$F$400,2) -> 0 | D29: =C29-B29 -> 0
A30: Shopping | B30: 0 | C30: =SUMIFS(Transactions!$E$4:$E$400,Transactions!$C$4:$C$400,$A30,Transactions!$F$4:$F$400,2) -> 0 | D30: =C30-B30 -> 0
A31: Personal Care | B31: 0 | C31: =SUMIFS(Transactions!$E$4:$E$400,Transactions!$C$4:$C$400,$A31,Transactions!$F$4:$F$400,2) -> 0 | D31: =C31-B31 -> 0
A32: Health / Medical | B32: 0 | C32: =SUMIFS(Transactions!$E$4:$E$400,Transactions!$C$4:$C$400,$A32,Transactions!$F$4:$F$400,2) -> 0 | D32: =C32-B32 -> 0
A33: Pet Care | B33: 0 | C33: =SUMIFS(Transactions!$E$4:$E$400,Transactions!$C$4:$C$400,$A33,Transactions!$F$4:$F$400,2) -> 0 | D33: =C33-B33 -> 0
A34: Childcare | B34: 0 | C34: =SUMIFS(Transactions!$E$4:$E$400,Transactions!$C$4:$C$400,$A34,Transactions!$F$4:$F$400,2) -> 0 | D34: =C34-B34 -> 0
A35: Gifts & Donations | B35: 0 | C35: =SUMIFS(Transactions!$E$4:$E$400,Transactions!$C$4:$C$400,$A35,Transactions!$F$4:$F$400,2) -> 0 | D35: =C35-B35 -> 0
A36: Travel | B36: 0 | C36: =SUMIFS(Transactions!$E$4:$E$400,Transactions!$C$4:$C$400,$A36,Transactions!$F$4:$F$400,2) -> 0 | D36: =C36-B36 -> 0
A37: Miscellaneous | B37: 0 | C37: =SUMIFS(Transactions!$E$4:$E$400,Transactions!$C$4:$C$400,$A37,Transactions!$F$4:$F$400,2) -> 0 | D37: =C37-B37 -> 0
A38: Total Variable Expenses | B38: =SUM(B26:B37) -> 0 | C38: =SUM(C26:C37) -> 0 | D38: =SUM(D26:D37) -> 0
A40: SAVINGS & DEBT
A41: Emergency Fund | B41: 0 | C41: =SUMIFS(Transactions!$E$4:$E$400,Transactions!$C$4:$C$400,$A41,Transactions!$F$4:$F$400,2) -> 0 | D41: =C41-B41 -> 0
A42: Retirement Savings | B42: 0 | C42: =SUMIFS(Transactions!$E$4:$E$400,Transactions!$C$4:$C$400,$A42,Transactions!$F$4:$F$400,2) -> 0 | D42: =C42-B42 -> 0
A43: Investment Contributions | B43: 0 | C43: =SUMIFS(Transactions!$E$4:$E$400,Transactions!$C$4:$C$400,$A43,Transactions!$F$4:$F$400,2) -> 0 | D43: =C43-B43 -> 0
A44: Debt Payoff | B44: 0 | C44: =SUMIFS(Transactions!$E$4:$E$400,Transactions!$C$4:$C$400,$A44,Transactions!$F$4:$F$400,2) -> 0 | D44: =C44-B44 -> 0
...

Sheet Mar
A1: ="MARCH"&" "&Welcome!$B$7&" BUDGET" -> MARCH 2026 BUDGET
A2: Plan it in BUDGETED, then let ACTUAL fill in from your Transactions log.
A4: CATEGORY | B4: BUDGETED | C4: ACTUAL | D4: VARIANCE
A5: INCOME
A6: Salary | B6: 0 | C6: =SUMIFS(Transactions!$E$4:$E$400,Transactions!$C$4:$C$400,$A6,Transactions!$F$4:$F$400,3) -> 0 | D6: =C6-B6 -> 0
A7: Freelance / Side Hustle | B7: 0 | C7: =SUMIFS(Transactions!$E$4:$E$400,Transactions!$C$4:$C$400,$A7,Transactions!$F$4:$F$400,3) -> 0 | D7: =C7-B7 -> 0
A8: Bonus | B8: 0 | C8: =SUMIFS(Transactions!$E$4:$E$400,Transactions!$C$4:$C$400,$A8,Transactions!$F$4:$F$400,3) -> 0 | D8: =C8-B8 -> 0
A9: Investment Income | B9: 0 | C9: =SUMIFS(Transactions!$E$4:$E$400,Transactions!$C$4:$C$400,$A9,Transactions!$F$4:$F$400,3) -> 0 | D9: =C9-B9 -> 0
A10: Gifts Received | B10: 0 | C10: =SUMIFS(Transactions!$E$4:$E$400,Transactions!$C$4:$C$400,$A10,Transactions!$F$4:$F$400,3) -> 0 | D10: =C10-B10 -> 0
A11: Other Income | B11: 0 | C11: =SUMIFS(Transactions!$E$4:$E$400,Transactions!$C$4:$C$400,$A11,Transactions!$F$4:$F$400,3) -> 0 | D11: =C11-B11 -> 0
A12: Total Income | B12: =SUM(B6:B11) -> 0 | C12: =SUM(C6:C11) -> 0 | D12: =SUM(D6:D11) -> 0
A14: FIXED EXPENSES
A15: Rent / Mortgage | B15: 0 | C15: =SUMIFS(Transactions!$E$4:$E$400,Transactions!$C$4:$C$400,$A15,Transactions!$F$4:$F$400,3) -> 0 | D15: =C15-B15 -> 0
A16: Utilities | B16: 0 | C16: =SUMIFS(Transactions!$E$4:$E$400,Transactions!$C$4:$C$400,$A16,Transactions!$F$4:$F$400,3) -> 0 | D16: =C16-B16 -> 0
A17: Insurance | B17: 0 | C17: =SUMIFS(Transactions!$E$4:$E$400,Transactions!$C$4:$C$400,$A17,Transactions!$F$4:$F$400,3) -> 0 | D17: =C17-B17 -> 0
A18: Phone Bill | B18: 0 | C18: =SUMIFS(Transactions!$E$4:$E$400,Transactions!$C$4:$C$400,$A18,Transactions!$F$4:$F$400,3) -> 0 | D18: =C18-B18 -> 0
A19: Internet | B19: 0 | C19: =SUMIFS(Transactions!$E$4:$E$400,Transactions!$C$4:$C$400,$A19,Transactions!$F$4:$F$400,3) -> 0 | D19: =C19-B19 -> 0
A20: Subscriptions | B20: 0 | C20: =SUMIFS(Transactions!$E$4:$E$400,Transactions!$C$4:$C$400,$A20,Transactions!$F$4:$F$400,3) -> 0 | D20: =C20-B20 -> 0
A21: Car Payment | B21: 0 | C21: =SUMIFS(Transactions!$E$4:$E$400,Transactions!$C$4:$C$400,$A21,Transactions!$F$4:$F$400,3) -> 0 | D21: =C21-B21 -> 0
A22: Loan Payments | B22: 0 | C22: =SUMIFS(Transactions!$E$4:$E$400,Transactions!$C$4:$C$400,$A22,Transactions!$F$4:$F$400,3) -> 0 | D22: =C22-B22 -> 0
A23: Total Fixed Expenses | B23: =SUM(B15:B22) -> 0 | C23: =SUM(C15:C22) -> 0 | D23: =SUM(D15:D22) -> 0
A25: VARIABLE EXPENSES
A26: Groceries | B26: 0 | C26: =SUMIFS(Transactions!$E$4:$E$400,Transactions!$C$4:$C$400,$A26,Transactions!$F$4:$F$400,3) -> 0 | D26: =C26-B26 -> 0
A27: Dining Out | B27: 0 | C27: =SUMIFS(Transactions!$E$4:$E$400,Transactions!$C$4:$C$400,$A27,Transactions!$F$4:$F$400,3) -> 0 | D27: =C27-B27 -> 0
A28: Transportation / Gas | B28: 0 | C28: =SUMIFS(Transactions!$E$4:$E$400,Transactions!$C$4:$C$400,$A28,Transactions!$F$4:$F$400,3) -> 0 | D28: =C28-B28 -> 0
A29: Entertainment | B29: 0 | C29: =SUMIFS(Transactions!$E$4:$E$400,Transactions!$C$4:$C$400,$A29,Transactions!$F$4:$F$400,3) -> 0 | D29: =C29-B29 -> 0
A30: Shopping | B30: 0 | C30: =SUMIFS(Transactions!$E$4:$E$400,Transactions!$C$4:$C$400,$A30,Transactions!$F$4:$F$400,3) -> 0 | D30: =C30-B30 -> 0
A31: Personal Care | B31: 0 | C31: =SUMIFS(Transactions!$E$4:$E$400,Transactions!$C$4:$C$400,$A31,Transactions!$F$4:$F$400,3) -> 0 | D31: =C31-B31 -> 0
A32: Health / Medical | B32: 0 | C32: =SUMIFS(Transactions!$E$4:$E$400,Transactions!$C$4:$C$400,$A32,Transactions!$F$4:$F$400,3) -> 0 | D32: =C32-B32 -> 0
A33: Pet Care | B33: 0 | C33: =SUMIFS(Transactions!$E$4:$E$400,Transactions!$C$4:$C$400,$A33,Transactions!$F$4:$F$400,3) -> 0 | D33: =C33-B33 -> 0
A34: Childcare | B34: 0 | C34: =SUMIFS(Transactions!$E$4:$E$400,Transactions!$C$4:$C$400,$A34,Transactions!$F$4:$F$400,3) -> 0 | D34: =C34-B34 -> 0
A35: Gifts & Donations | B35: 0 | C35: =SUMIFS(Transactions!$E$4:$E$400,Transactions!$C$4:$C$400,$A35,Transactions!$F$4:$F$400,3) -> 0 | D35: =C35-B35 -> 0
A36: Travel | B36: 0 | C36: =SUMIFS(Transactions!$E$4:$E$400,Transactions!$C$4:$C$400,$A36,Transactions!$F$4:$F$400,3) -> 0 | D36: =C36-B36 -> 0
A37: Miscellaneous | B37: 0 | C37: =SUMIFS(Transactions!$E$4:$E$400,Transactions!$C$4:$C$400,$A37,Transactions!$F$4:$F$400,3) -> 0 | D37: =C37-B37 -> 0
A38: Total Variable Expenses | B38: =SUM(B26:B37) -> 0 | C38: =SUM(C26:C37) -> 0 | D38: =SUM(D26:D37) -> 0
A40: SAVINGS & DEBT
A41: Emergency Fund | B41: 0 | C41: =SUMIFS(Transactions!$E$4:$E$400,Transactions!$C$4:$C$400,$A41,Transactions!$F$4:$F$400,3) -> 0 | D41: =C41-B41 -> 0
A42: Retirement Savings | B42: 0 | C42: =SUMIFS(Transactions!$E$4:$E$400,Transactions!$C$4:$C$400,$A42,Transactions!$F$4:$F$400,3) -> 0 | D42: =C42-B42 -> 0
A43: Investment Contributions | B43: 0 | C43: =SUMIFS(Transactions!$E$4:$E$400,Transactions!$C$4:$C$400,$A43,Transactions!$F$4:$F$400,3) -> 0 | D43: =C43-B43 -> 0
A44: Debt Payoff | B44: 0 | C44: =SUMIFS(Transactions!$E$4:$E$400,Transactions!$C$4:$C$400,$A44,Transactions!$F$4:$F$400,3) -> 0 | D44: =C44-B44 -> 0
...

Sheet Apr
A1: ="APRIL"&" "&Welcome!$B$7&" BUDGET" -> APRIL 2026 BUDGET
A2: Plan it in BUDGETED, then let ACTUAL fill in from your Transactions log.
A4: CATEGORY | B4: BUDGETED | C4: ACTUAL | D4: VARIANCE
A5: INCOME
A6: Salary | B6: 0 | C6: =SUMIFS(Transactions!$E$4:$E$400,Transactions!$C$4:$C$400,$A6,Transactions!$F$4:$F$400,4) -> 0 | D6: =C6-B6 -> 0
A7: Freelance / Side Hustle | B7: 0 | C7: =SUMIFS(Transactions!$E$4:$E$400,Transactions!$C$4:$C$400,$A7,Transactions!$F$4:$F$400,4) -> 0 | D7: =C7-B7 -> 0
A8: Bonus | B8: 0 | C8: =SUMIFS(Transactions!$E$4:$E$400,Transactions!$C$4:$C$400,$A8,Transactions!$F$4:$F$400,4) -> 0 | D8: =C8-B8 -> 0
A9: Investment Income | B9: 0 | C9: =SUMIFS(Transactions!$E$4:$E$400,Transactions!$C$4:$C$400,$A9,Transactions!$F$4:$F$400,4) -> 0 | D9: =C9-B9 -> 0
A10: Gifts Received | B10: 0 | C10: =SUMIFS(Transactions!$E$4:$E$400,Transactions!$C$4:$C$400,$A10,Transactions!$F$4:$F$400,4) -> 0 | D10: =C10-B10 -> 0
A11: Other Income | B11: 0 | C11: =SUMIFS(Transactions!$E$4:$E$400,Transactions!$C$4:$C$400,$A11,Transactions!$F$4:$F$400,4) -> 0 | D11: =C11-B11 -> 0
A12: Total Income | B12: =SUM(B6:B11) -> 0 | C12: =SUM(C6:C11) -> 0 | D12: =SUM(D6:D11) -> 0
A14: FIXED EXPENSES
A15: Rent / Mortgage | B15: 0 | C15: =SUMIFS(Transactions!$E$4:$E$400,Transactions!$C$4:$C$400,$A15,Transactions!$F$4:$F$400,4) -> 0 | D15: =C15-B15 -> 0
A16: Utilities | B16: 0 | C16: =SUMIFS(Transactions!$E$4:$E$400,Transactions!$C$4:$C$400,$A16,Transactions!$F$4:$F$400,4) -> 0 | D16: =C16-B16 -> 0
A17: Insurance | B17: 0 | C17: =SUMIFS(Transactions!$E$4:$E$400,Transactions!$C$4:$C$400,$A17,Transactions!$F$4:$F$400,4) -> 0 | D17: =C17-B17 -> 0
A18: Phone Bill | B18: 0 | C18: =SUMIFS(Transactions!$E$4:$E$400,Transactions!$C$4:$C$400,$A18,Transactions!$F$4:$F$400,4) -> 0 | D18: =C18-B18 -> 0
A19: Internet | B19: 0 | C19: =SUMIFS(Transactions!$E$4:$E$400,Transactions!$C$4:$C$400,$A19,Transactions!$F$4:$F$400,4) -> 0 | D19: =C19-B19 -> 0
A20: Subscriptions | B20: 0 | C20: =SUMIFS(Transactions!$E$4:$E$400,Transactions!$C$4:$C$400,$A20,Transactions!$F$4:$F$400,4) -> 0 | D20: =C20-B20 -> 0
A21: Car Payment | B21: 0 | C21: =SUMIFS(Transactions!$E$4:$E$400,Transactions!$C$4:$C$400,$A21,Transactions!$F$4:$F$400,4) -> 0 | D21: =C21-B21 -> 0
A22: Loan Payments | B22: 0 | C22: =SUMIFS(Transactions!$E$4:$E$400,Transactions!$C$4:$C$400,$A22,Transactions!$F$4:$F$400,4) -> 0 | D22: =C22-B22 -> 0
A23: Total Fixed Expenses | B23: =SUM(B15:B22) -> 0 | C23: =SUM(C15:C22) -> 0 | D23: =SUM(D15:D22) -> 0
A25: VARIABLE EXPENSES
A26: Groceries | B26: 0 | C26: =SUMIFS(Transactions!$E$4:$E$400,Transactions!$C$4:$C$400,$A26,Transactions!$F$4:$F$400,4) -> 0 | D26: =C26-B26 -> 0
A27: Dining Out | B27: 0 | C27: =SUMIFS(Transactions!$E$4:$E$400,Transactions!$C$4:$C$400,$A27,Transactions!$F$4:$F$400,4) -> 0 | D27: =C27-B27 -> 0
A28: Transportation / Gas | B28: 0 | C28: =SUMIFS(Transactions!$E$4:$E$400,Transactions!$C$4:$C$400,$A28,Transactions!$F$4:$F$400,4) -> 0 | D28: =C28-B28 -> 0
A29: Entertainment | B29: 0 | C29: =SUMIFS(Transactions!$E$4:$E$400,Transactions!$C$4:$C$400,$A29,Transactions!$F$4:$F$400,4) -> 0 | D29: =C29-B29 -> 0
A30: Shopping | B30: 0 | C30: =SUMIFS(Transactions!$E$4:$E$400,Transactions!$C$4:$C$400,$A30,Transactions!$F$4:$F$400,4) -> 0 | D30: =C30-B30 -> 0
A31: Personal Care | B31: 0 | C31: =SUMIFS(Transactions!$E$4:$E$400,Transactions!$C$4:$C$400,$A31,Transactions!$F$4:$F$400,4) -> 0 | D31: =C31-B31 -> 0
A32: Health / Medical | B32: 0 | C32: =SUMIFS(Transactions!$E$4:$E$400,Transactions!$C$4:$C$400,$A32,Transactions!$F$4:$F$400,4) -> 0 | D32: =C32-B32 -> 0
A33: Pet Care | B33: 0 | C33: =SUMIFS(Transactions!$E$4:$E$400,Transactions!$C$4:$C$400,$A33,Transactions!$F$4:$F$400,4) -> 0 | D33: =C33-B33 -> 0
A34: Childcare | B34: 0 | C34: =SUMIFS(Transactions!$E$4:$E$400,Transactions!$C$4:$C$400,$A34,Transactions!$F$4:$F$400,4) -> 0 | D34: =C34-B34 -> 0
A35: Gifts & Donations | B35: 0 | C35: =SUMIFS(Transactions!$E$4:$E$400,Transactions!$C$4:$C$400,$A35,Transactions!$F$4:$F$400,4) -> 0 | D35: =C35-B35 -> 0
A36: Travel | B36: 0 | C36: =SUMIFS(Transactions!$E$4:$E$400,Transactions!$C$4:$C$400,$A36,Transactions!$F$4:$F$400,4) -> 0 | D36: =C36-B36 -> 0
A37: Miscellaneous | B37: 0 | C37: =SUMIFS(Transactions!$E$4:$E$400,Transactions!$C$4:$C$400,$A37,Transactions!$F$4:$F$400,4) -> 0 | D37: =C37-B37 -> 0
A38: Total Variable Expenses | B38: =SUM(B26:B37) -> 0 | C38: =SUM(C26:C37) -> 0 | D38: =SUM(D26:D37) -> 0
A40: SAVINGS & DEBT
A41: Emergency Fund | B41: 0 | C41: =SUMIFS(Transactions!$E$4:$E$400,Transactions!$C$4:$C$400,$A41,Transactions!$F$4:$F$400,4) -> 0 | D41: =C41-B41 -> 0
A42: Retirement Savings | B42: 0 | C42: =SUMIFS(Transactions!$E$4:$E$400,Transactions!$C$4:$C$400,$A42,Transactions!$F$4:$F$400,4) -> 0 | D42: =C42-B42 -> 0
A43: Investment Contributions | B43: 0 | C43: =SUMIFS(Transactions!$E$4:$E$400,Transactions!$C$4:$C$400,$A43,Transactions!$F$4:$F$400,4) -> 0 | D43: =C43-B43 -> 0
A44: Debt Payoff | B44: 0 | C44: =SUMIFS(Transactions!$E$4:$E$400,Transactions!$C$4:$C$400,$A44,Transactions!$F$4:$F$400,4) -> 0 | D44: =C44-B44 -> 0
...

Sheet May
A1: ="MAY"&" "&Welcome!$B$7&" BUDGET" -> MAY 2026 BUDGET
A2: Plan it in BUDGETED, then let ACTUAL fill in from your Transactions log.
A4: CATEGORY | B4: BUDGETED | C4: ACTUAL | D4: VARIANCE
A5: INCOME
A6: Salary | B6: 0 | C6: =SUMIFS(Transactions!$E$4:$E$400,Transactions!$C$4:$C$400,$A6,Transactions!$F$4:$F$400,5) -> 0 | D6: =C6-B6 -> 0
A7: Freelance / Side Hustle | B7: 0 | C7: =SUMIFS(Transactions!$E$4:$E$400,Transactions!$C$4:$C$400,$A7,Transactions!$F$4:$F$400,5) -> 0 | D7: =C7-B7 -> 0
A8: Bonus | B8: 0 | C8: =SUMIFS(Transactions!$E$4:$E$400,Transactions!$C$4:$C$400,$A8,Transactions!$F$4:$F$400,5) -> 0 | D8: =C8-B8 -> 0
A9: Investment Income | B9: 0 | C9: =SUMIFS(Transactions!$E$4:$E$400,Transactions!$C$4:$C$400,$A9,Transactions!$F$4:$F$400,5) -> 0 | D9: =C9-B9 -> 0
A10: Gifts Received | B10: 0 | C10: =SUMIFS(Transactions!$E$4:$E$400,Transactions!$C$4:$C$400,$A10,Transactions!$F$4:$F$400,5) -> 0 | D10: =C10-B10 -> 0
A11: Other Income | B11: 0 | C11: =SUMIFS(Transactions!$E$4:$E$400,Transactions!$C$4:$C$400,$A11,Transactions!$F$4:$F$400,5) -> 0 | D11: =C11-B11 -> 0
A12: Total Income | B12: =SUM(B6:B11) -> 0 | C12: =SUM(C6:C11) -> 0 | D12: =SUM(D6:D11) -> 0
A14: FIXED EXPENSES
A15: Rent / Mortgage | B15: 0 | C15: =SUMIFS(Transactions!$E$4:$E$400,Transactions!$C$4:$C$400,$A15,Transactions!$F$4:$F$400,5) -> 0 | D15: =C15-B15 -> 0
A16: Utilities | B16: 0 | C16: =SUMIFS(Transactions!$E$4:$E$400,Transactions!$C$4:$C$400,$A16,Transactions!$F$4:$F$400,5) -> 0 | D16: =C16-B16 -> 0
A17: Insurance | B17: 0 | C17: =SUMIFS(Transactions!$E$4:$E$400,Transactions!$C$4:$C$400,$A17,Transactions!$F$4:$F$400,5) -> 0 | D17: =C17-B17 -> 0
A18: Phone Bill | B18: 0 | C18: =SUMIFS(Transactions!$E$4:$E$400,Transactions!$C$4:$C$400,$A18,Transactions!$F$4:$F$400,5) -> 0 | D18: =C18-B18 -> 0
A19: Internet | B19: 0 | C19: =SUMIFS(Transactions!$E$4:$E$400,Transactions!$C$4:$C$400,$A19,Transactions!$F$4:$F$400,5) -> 0 | D19: =C19-B19 -> 0
A20: Subscriptions | B20: 0 | C20: =SUMIFS(Transactions!$E$4:$E$400,Transactions!$C$4:$C$400,$A20,Transactions!$F$4:$F$400,5) -> 0 | D20: =C20-B20 -> 0
A21: Car Payment | B21: 0 | C21: =SUMIFS(Transactions!$E$4:$E$400,Transactions!$C$4:$C$400,$A21,Transactions!$F$4:$F$400,5) -> 0 | D21: =C21-B21 -> 0
A22: Loan Payments | B22: 0 | C22: =SUMIFS(Transactions!$E$4:$E$400,Transactions!$C$4:$C$400,$A22,Transactions!$F$4:$F$400,5) -> 0 | D22: =C22-B22 -> 0
A23: Total Fixed Expenses | B23: =SUM(B15:B22) -> 0 | C23: =SUM(C15:C22) -> 0 | D23: =SUM(D15:D22) -> 0
A25: VARIABLE EXPENSES
A26: Groceries | B26: 0 | C26: =SUMIFS(Transactions!$E$4:$E$400,Transactions!$C$4:$C$400,$A26,Transactions!$F$4:$F$400,5) -> 0 | D26: =C26-B26 -> 0
A27: Dining Out | B27: 0 | C27: =SUMIFS(Transactions!$E$4:$E$400,Transactions!$C$4:$C$400,$A27,Transactions!$F$4:$F$400,5) -> 0 | D27: =C27-B27 -> 0
A28: Transportation / Gas | B28: 0 | C28: =SUMIFS(Transactions!$E$4:$E$400,Transactions!$C$4:$C$400,$A28,Transactions!$F$4:$F$400,5) -> 0 | D28: =C28-B28 -> 0
A29: Entertainment | B29: 0 | C29: =SUMIFS(Transactions!$E$4:$E$400,Transactions!$C$4:$C$400,$A29,Transactions!$F$4:$F$400,5) -> 0 | D29: =C29-B29 -> 0
A30: Shopping | B30: 0 | C30: =SUMIFS(Transactions!$E$4:$E$400,Transactions!$C$4:$C$400,$A30,Transactions!$F$4:$F$400,5) -> 0 | D30: =C30-B30 -> 0
A31: Personal Care | B31: 0 | C31: =SUMIFS(Transactions!$E$4:$E$400,Transactions!$C$4:$C$400,$A31,Transactions!$F$4:$F$400,5) -> 0 | D31: =C31-B31 -> 0
A32: Health / Medical | B32: 0 | C32: =SUMIFS(Transactions!$E$4:$E$400,Transactions!$C$4:$C$400,$A32,Transactions!$F$4:$F$400,5) -> 0 | D32: =C32-B32 -> 0
A33: Pet Care | B33: 0 | C33: =SUMIFS(Transactions!$E$4:$E$400,Transactions!$C$4:$C$400,$A33,Transactions!$F$4:$F$400,5) -> 0 | D33: =C33-B33 -> 0
A34: Childcare | B34: 0 | C34: =SUMIFS(Transactions!$E$4:$E$400,Transactions!$C$4:$C$400,$A34,Transactions!$F$4:$F$400,5) -> 0 | D34: =C34-B34 -> 0
A35: Gifts & Donations | B35: 0 | C35: =SUMIFS(Transactions!$E$4:$E$400,Transactions!$C$4:$C$400,$A35,Transactions!$F$4:$F$400,5) -> 0 | D35: =C35-B35 -> 0
A36: Travel | B36: 0 | C36: =SUMIFS(Transactions!$E$4:$E$400,Transactions!$C$4:$C$400,$A36,Transactions!$F$4:$F$400,5) -> 0 | D36: =C36-B36 -> 0
A37: Miscellaneous | B37: 0 | C37: =SUMIFS(Transactions!$E$4:$E$400,Transactions!$C$4:$C$400,$A37,Transactions!$F$4:$F$400,5) -> 0 | D37: =C37-B37 -> 0
A38: Total Variable Expenses | B38: =SUM(B26:B37) -> 0 | C38: =SUM(C26:C37) -> 0 | D38: =SUM(D26:D37) -> 0
A40: SAVINGS & DEBT
A41: Emergency Fund | B41: 0 | C41: =SUMIFS(Transactions!$E$4:$E$400,Transactions!$C$4:$C$400,$A41,Transactions!$F$4:$F$400,5) -> 0 | D41: =C41-B41 -> 0
A42: Retirement Savings | B42: 0 | C42: =SUMIFS(Transactions!$E$4:$E$400,Transactions!$C$4:$C$400,$A42,Transactions!$F$4:$F$400,5) -> 0 | D42: =C42-B42 -> 0
A43: Investment Contributions | B43: 0 | C43: =SUMIFS(Transactions!$E$4:$E$400,Transactions!$C$4:$C$400,$A43,Transactions!$F$4:$F$400,5) -> 0 | D43: =C43-B43 -> 0
A44: Debt Payoff | B44: 0 | C44: =SUMIFS(Transactions!$E$4:$E$400,Transactions!$C$4:$C$400,$A44,Transactions!$F$4:$F$400,5) -> 0 | D44: =C44-B44 -> 0
...

Sheet Jun
A1: ="JUNE"&" "&Welcome!$B$7&" BUDGET" -> JUNE 2026 BUDGET
A2: Plan it in BUDGETED, then let ACTUAL fill in from your Transactions log.
A4: CATEGORY | B4: BUDGETED | C4: ACTUAL | D4: VARIANCE
A5: INCOME
A6: Salary | B6: 0 | C6: =SUMIFS(Transactions!$E$4:$E$400,Transactions!$C$4:$C$400,$A6,Transactions!$F$4:$F$400,6) -> 0 | D6: =C6-B6 -> 0
A7: Freelance / Side Hustle | B7: 0 | C7: =SUMIFS(Transactions!$E$4:$E$400,Transactions!$C$4:$C$400,$A7,Transactions!$F$4:$F$400,6) -> 0 | D7: =C7-B7 -> 0
A8: Bonus | B8: 0 | C8: =SUMIFS(Transactions!$E$4:$E$400,Transactions!$C$4:$C$400,$A8,Transactions!$F$4:$F$400,6) -> 0 | D8: =C8-B8 -> 0
A9: Investment Income | B9: 0 | C9: =SUMIFS(Transactions!$E$4:$E$400,Transactions!$C$4:$C$400,$A9,Transactions!$F$4:$F$400,6) -> 0 | D9: =C9-B9 -> 0
A10: Gifts Received | B10: 0 | C10: =SUMIFS(Transactions!$E$4:$E$400,Transactions!$C$4:$C$400,$A10,Transactions!$F$4:$F$400,6) -> 0 | D10: =C10-B10 -> 0
A11: Other Income | B11: 0 | C11: =SUMIFS(Transactions!$E$4:$E$400,Transactions!$C$4:$C$400,$A11,Transactions!$F$4:$F$400,6) -> 0 | D11: =C11-B11 -> 0
A12: Total Income | B12: =SUM(B6:B11) -> 0 | C12: =SUM(C6:C11) -> 0 | D12: =SUM(D6:D11) -> 0
A14: FIXED EXPENSES
A15: Rent / Mortgage | B15: 0 | C15: =SUMIFS(Transactions!$E$4:$E$400,Transactions!$C$4:$C$400,$A15,Transactions!$F$4:$F$400,6) -> 0 | D15: =C15-B15 -> 0
A16: Utilities | B16: 0 | C16: =SUMIFS(Transactions!$E$4:$E$400,Transactions!$C$4:$C$400,$A16,Transactions!$F$4:$F$400,6) -> 0 | D16: =C16-B16 -> 0
A17: Insurance | B17: 0 | C17: =SUMIFS(Transactions!$E$4:$E$400,Transactions!$C$4:$C$400,$A17,Transactions!$F$4:$F$400,6) -> 0 | D17: =C17-B17 -> 0
A18: Phone Bill | B18: 0 | C18: =SUMIFS(Transactions!$E$4:$E$400,Transactions!$C$4:$C$400,$A18,Transactions!$F$4:$F$400,6) -> 0 | D18: =C18-B18 -> 0
A19: Internet | B19: 0 | C19: =SUMIFS(Transactions!$E$4:$E$400,Transactions!$C$4:$C$400,$A19,Transactions!$F$4:$F$400,6) -> 0 | D19: =C19-B19 -> 0
A20: Subscriptions | B20: 0 | C20: =SUMIFS(Transactions!$E$4:$E$400,Transactions!$C$4:$C$400,$A20,Transactions!$F$4:$F$400,6) -> 0 | D20: =C20-B20 -> 0
A21: Car Payment | B21: 0 | C21: =SUMIFS(Transactions!$E$4:$E$400,Transactions!$C$4:$C$400,$A21,Transactions!$F$4:$F$400,6) -> 0 | D21: =C21-B21 -> 0
A22: Loan Payments | B22: 0 | C22: =SUMIFS(Transactions!$E$4:$E$400,Transactions!$C$4:$C$400,$A22,Transactions!$F$4:$F$400,6) -> 0 | D22: =C22-B22 -> 0
A23: Total Fixed Expenses | B23: =SUM(B15:B22) -> 0 | C23: =SUM(C15:C22) -> 0 | D23: =SUM(D15:D22) -> 0
A25: VARIABLE EXPENSES
A26: Groceries | B26: 0 | C26: =SUMIFS(Transactions!$E$4:$E$400,Transactions!$C$4:$C$400,$A26,Transactions!$F$4:$F$400,6) -> 0 | D26: =C26-B26 -> 0
A27: Dining Out | B27: 0 | C27: =SUMIFS(Transactions!$E$4:$E$400,Transactions!$C$4:$C$400,$A27,Transactions!$F$4:$F$400,6) -> 0 | D27: =C27-B27 -> 0
A28: Transportation / Gas | B28: 0 | C28: =SUMIFS(Transactions!$E$4:$E$400,Transactions!$C$4:$C$400,$A28,Transactions!$F$4:$F$400,6) -> 0 | D28: =C28-B28 -> 0
A29: Entertainment | B29: 0 | C29: =SUMIFS(Transactions!$E$4:$E$400,Transactions!$C$4:$C$400,$A29,Transactions!$F$4:$F$400,6) -> 0 | D29: =C29-B29 -> 0
A30: Shopping | B30: 0 | C30: =SUMIFS(Transactions!$E$4:$E$400,Transactions!$C$4:$C$400,$A30,Transactions!$F$4:$F$400,6) -> 0 | D30: =C30-B30 -> 0
A31: Personal Care | B31: 0 | C31: =SUMIFS(Transactions!$E$4:$E$400,Transactions!$C$4:$C$400,$A31,Transactions!$F$4:$F$400,6) -> 0 | D31: =C31-B31 -> 0
A32: Health / Medical | B32: 0 | C32: =SUMIFS(Transactions!$E$4:$E$400,Transactions!$C$4:$C$400,$A32,Transactions!$F$4:$F$400,6) -> 0 | D32: =C32-B32 -> 0
A33: Pet Care | B33: 0 | C33: =SUMIFS(Transactions!$E$4:$E$400,Transactions!$C$4:$C$400,$A33,Transactions!$F$4:$F$400,6) -> 0 | D33: =C33-B33 -> 0
A34: Childcare | B34: 0 | C34: =SUMIFS(Transactions!$E$4:$E$400,Transactions!$C$4:$C$400,$A34,Transactions!$F$4:$F$400,6) -> 0 | D34: =C34-B34 -> 0
A35: Gifts & Donations | B35: 0 | C35: =SUMIFS(Transactions!$E$4:$E$400,Transactions!$C$4:$C$400,$A35,Transactions!$F$4:$F$400,6) -> 0 | D35: =C35-B35 -> 0
A36: Travel | B36: 0 | C36: =SUMIFS(Transactions!$E$4:$E$400,Transactions!$C$4:$C$400,$A36,Transactions!$F$4:$F$400,6) -> 0 | D36: =C36-B36 -> 0
A37: Miscellaneous | B37: 0 | C37: =SUMIFS(Transactions!$E$4:$E$400,Transactions!$C$4:$C$400,$A37,Transactions!$F$4:$F$400,6) -> 0 | D37: =C37-B37 -> 0
A38: Total Variable Expenses | B38: =SUM(B26:B37) -> 0 | C38: =SUM(C26:C37) -> 0 | D38: =SUM(D26:D37) -> 0
A40: SAVINGS & DEBT
A41: Emergency Fund | B41: 0 | C41: =SUMIFS(Transactions!$E$4:$E$400,Transactions!$C$4:$C$400,$A41,Transactions!$F$4:$F$400,6) -> 0 | D41: =C41-B41 -> 0
A42: Retirement Savings | B42: 0 | C42: =SUMIFS(Transactions!$E$4:$E$400,Transactions!$C$4:$C$400,$A42,Transactions!$F$4:$F$400,6) -> 0 | D42: =C42-B42 -> 0
A43: Investment Contributions | B43: 0 | C43: =SUMIFS(Transactions!$E$4:$E$400,Transactions!$C$4:$C$400,$A43,Transactions!$F$4:$F$400,6) -> 0 | D43: =C43-B43 -> 0
A44: Debt Payoff | B44: 0 | C44: =SUMIFS(Transactions!$E$4:$E$400,Transactions!$C$4:$C$400,$A44,Transactions!$F$4:$F$400,6) -> 0 | D44: =C44-B44 -> 0
...

Sheet Jul
A1: ="JULY"&" "&Welcome!$B$7&" BUDGET" -> JULY 2026 BUDGET
A2: Plan it in BUDGETED, then let ACTUAL fill in from your Transactions log.
A4: CATEGORY | B4: BUDGETED | C4: ACTUAL | D4: VARIANCE
A5: INCOME
A6: Salary | B6: 0 | C6: =SUMIFS(Transactions!$E$4:$E$400,Transactions!$C$4:$C$400,$A6,Transactions!$F$4:$F$400,7) -> 0 | D6: =C6-B6 -> 0
A7: Freelance / Side Hustle | B7: 0 | C7: =SUMIFS(Transactions!$E$4:$E$400,Transactions!$C$4:$C$400,$A7,Transactions!$F$4:$F$400,7) -> 0 | D7: =C7-B7 -> 0
A8: Bonus | B8: 0 | C8: =SUMIFS(Transactions!$E$4:$E$400,Transactions!$C$4:$C$400,$A8,Transactions!$F$4:$F$400,7) -> 0 | D8: =C8-B8 -> 0
A9: Investment Income | B9: 0 | C9: =SUMIFS(Transactions!$E$4:$E$400,Transactions!$C$4:$C$400,$A9,Transactions!$F$4:$F$400,7) -> 0 | D9: =C9-B9 -> 0
A10: Gifts Received | B10: 0 | C10: =SUMIFS(Transactions!$E$4:$E$400,Transactions!$C$4:$C$400,$A10,Transactions!$F$4:$F$400,7) -> 0 | D10: =C10-B10 -> 0
A11: Other Income | B11: 0 | C11: =SUMIFS(Transactions!$E$4:$E$400,Transactions!$C$4:$C$400,$A11,Transactions!$F$4:$F$400,7) -> 0 | D11: =C11-B11 -> 0
A12: Total Income | B12: =SUM(B6:B11) -> 0 | C12: =SUM(C6:C11) -> 0 | D12: =SUM(D6:D11) -> 0
A14: FIXED EXPENSES
A15: Rent / Mortgage | B15: 0 | C15: =SUMIFS(Transactions!$E$4:$E$400,Transactions!$C$4:$C$400,$A15,Transactions!$F$4:$F$400,7) -> 0 | D15: =C15-B15 -> 0
A16: Utilities | B16: 0 | C16: =SUMIFS(Transactions!$E$4:$E$400,Transactions!$C$4:$C$400,$A16,Transactions!$F$4:$F$400,7) -> 0 | D16: =C16-B16 -> 0
A17: Insurance | B17: 0 | C17: =SUMIFS(Transactions!$E$4:$E$400,Transactions!$C$4:$C$400,$A17,Transactions!$F$4:$F$400,7) -> 0 | D17: =C17-B17 -> 0
A18: Phone Bill | B18: 0 | C18: =SUMIFS(Transactions!$E$4:$E$400,Transactions!$C$4:$C$400,$A18,Transactions!$F$4:$F$400,7) -> 0 | D18: =C18-B18 -> 0
A19: Internet | B19: 0 | C19: =SUMIFS(Transactions!$E$4:$E$400,Transactions!$C$4:$C$400,$A19,Transactions!$F$4:$F$400,7) -> 0 | D19: =C19-B19 -> 0
A20: Subscriptions | B20: 0 | C20: =SUMIFS(Transactions!$E$4:$E$400,Transactions!$C$4:$C$400,$A20,Transactions!$F$4:$F$400,7) -> 0 | D20: =C20-B20 -> 0
A21: Car Payment | B21: 0 | C21: =SUMIFS(Transactions!$E$4:$E$400,Transactions!$C$4:$C$400,$A21,Transactions!$F$4:$F$400,7) -> 0 | D21: =C21-B21 -> 0
A22: Loan Payments | B22: 0 | C22: =SUMIFS(Transactions!$E$4:$E$400,Transactions!$C$4:$C$400,$A22,Transactions!$F$4:$F$400,7) -> 0 | D22: =C22-B22 -> 0
A23: Total Fixed Expenses | B23: =SUM(B15:B22) -> 0 | C23: =SUM(C15:C22) -> 0 | D23: =SUM(D15:D22) -> 0
A25: VARIABLE EXPENSES
A26: Groceries | B26: 0 | C26: =SUMIFS(Transactions!$E$4:$E$400,Transactions!$C$4:$C$400,$A26,Transactions!$F$4:$F$400,7) -> 0 | D26: =C26-B26 -> 0
A27: Dining Out | B27: 0 | C27: =SUMIFS(Transactions!$E$4:$E$400,Transactions!$C$4:$C$400,$A27,Transactions!$F$4:$F$400,7) -> 0 | D27: =C27-B27 -> 0
A28: Transportation / Gas | B28: 0 | C28: =SUMIFS(Transactions!$E$4:$E$400,Transactions!$C$4:$C$400,$A28,Transactions!$F$4:$F$400,7) -> 0 | D28: =C28-B28 -> 0
A29: Entertainment | B29: 0 | C29: =SUMIFS(Transactions!$E$4:$E$400,Transactions!$C$4:$C$400,$A29,Transactions!$F$4:$F$400,7) -> 0 | D29: =C29-B29 -> 0
A30: Shopping | B30: 0 | C30: =SUMIFS(Transactions!$E$4:$E$400,Transactions!$C$4:$C$400,$A30,Transactions!$F$4:$F$400,7) -> 0 | D30: =C30-B30 -> 0
A31: Personal Care | B31: 0 | C31: =SUMIFS(Transactions!$E$4:$E$400,Transactions!$C$4:$C$400,$A31,Transactions!$F$4:$F$400,7) -> 0 | D31: =C31-B31 -> 0
A32: Health / Medical | B32: 0 | C32: =SUMIFS(Transactions!$E$4:$E$400,Transactions!$C$4:$C$400,$A32,Transactions!$F$4:$F$400,7) -> 0 | D32: =C32-B32 -> 0
A33: Pet Care | B33: 0 | C33: =SUMIFS(Transactions!$E$4:$E$400,Transactions!$C$4:$C$400,$A33,Transactions!$F$4:$F$400,7) -> 0 | D33: =C33-B33 -> 0
A34: Childcare | B34: 0 | C34: =SUMIFS(Transactions!$E$4:$E$400,Transactions!$C$4:$C$400,$A34,Transactions!$F$4:$F$400,7) -> 0 | D34: =C34-B34 -> 0
A35: Gifts & Donations | B35: 0 | C35: =SUMIFS(Transactions!$E$4:$E$400,Transactions!$C$4:$C$400,$A35,Transactions!$F$4:$F$400,7) -> 0 | D35: =C35-B35 -> 0
A36: Travel | B36: 0 | C36: =SUMIFS(Transactions!$E$4:$E$400,Transactions!$C$4:$C$400,$A36,Transactions!$F$4:$F$400,7) -> 0 | D36: =C36-B36 -> 0
A37: Miscellaneous | B37: 0 | C37: =SUMIFS(Transactions!$E$4:$E$400,Transactions!$C$4:$C$400,$A37,Transactions!$F$4:$F$400,7) -> 0 | D37: =C37-B37 -> 0
A38: Total Variable Expenses | B38: =SUM(B26:B37) -> 0 | C38: =SUM(C26:C37) -> 0 | D38: =SUM(D26:D37) -> 0
A40: SAVINGS & DEBT
A41: Emergency Fund | B41: 0 | C41: =SUMIFS(Transactions!$E$4:$E$400,Transactions!$C$4:$C$400,$A41,Transactions!$F$4:$F$400,7) -> 0 | D41: =C41-B41 -> 0
A42: Retirement Savings | B42: 0 | C42: =SUMIFS(Transactions!$E$4:$E$400,Transactions!$C$4:$C$400,$A42,Transactions!$F$4:$F$400,7) -> 0 | D42: =C42-B42 -> 0
A43: Investment Contributions | B43: 0 | C43: =SUMIFS(Transactions!$E$4:$E$400,Transactions!$C$4:$C$400,$A43,Transactions!$F$4:$F$400,7) -> 0 | D43: =C43-B43 -> 0
A44: Debt Payoff | B44: 0 | C44: =SUMIFS(Transactions!$E$4:$E$400,Transactions!$C$4:$C$400,$A44,Transactions!$F$4:$F$400,7) -> 0 | D44: =C44-B44 -> 0
...

Sheet Aug
A1: ="AUGUST"&" "&Welcome!$B$7&" BUDGET" -> AUGUST 2026 BUDGET
A2: Plan it in BUDGETED, then let ACTUAL fill in from your Transactions log.
A4: CATEGORY | B4: BUDGETED | C4: ACTUAL | D4: VARIANCE
A5: INCOME
A6: Salary | B6: 0 | C6: =SUMIFS(Transactions!$E$4:$E$400,Transactions!$C$4:$C$400,$A6,Transactions!$F$4:$F$400,8) -> 0 | D6: =C6-B6 -> 0
A7: Freelance / Side Hustle | B7: 0 | C7: =SUMIFS(Transactions!$E$4:$E$400,Transactions!$C$4:$C$400,$A7,Transactions!$F$4:$F$400,8) -> 0 | D7: =C7-B7 -> 0
A8: Bonus | B8: 0 | C8: =SUMIFS(Transactions!$E$4:$E$400,Transactions!$C$4:$C$400,$A8,Transactions!$F$4:$F$400,8) -> 0 | D8: =C8-B8 -> 0
A9: Investment Income | B9: 0 | C9: =SUMIFS(Transactions!$E$4:$E$400,Transactions!$C$4:$C$400,$A9,Transactions!$F$4:$F$400,8) -> 0 | D9: =C9-B9 -> 0
A10: Gifts Received | B10: 0 | C10: =SUMIFS(Transactions!$E$4:$E$400,Transactions!$C$4:$C$400,$A10,Transactions!$F$4:$F$400,8) -> 0 | D10: =C10-B10 -> 0
A11: Other Income | B11: 0 | C11: =SUMIFS(Transactions!$E$4:$E$400,Transactions!$C$4:$C$400,$A11,Transactions!$F$4:$F$400,8) -> 0 | D11: =C11-B11 -> 0
A12: Total Income | B12: =SUM(B6:B11) -> 0 | C12: =SUM(C6:C11) -> 0 | D12: =SUM(D6:D11) -> 0
A14: FIXED EXPENSES
A15: Rent / Mortgage | B15: 0 | C15: =SUMIFS(Transactions!$E$4:$E$400,Transactions!$C$4:$C$400,$A15,Transactions!$F$4:$F$400,8) -> 0 | D15: =C15-B15 -> 0
A16: Utilities | B16: 0 | C16: =SUMIFS(Transactions!$E$4:$E$400,Transactions!$C$4:$C$400,$A16,Transactions!$F$4:$F$400,8) -> 0 | D16: =C16-B16 -> 0
A17: Insurance | B17: 0 | C17: =SUMIFS(Transactions!$E$4:$E$400,Transactions!$C$4:$C$400,$A17,Transactions!$F$4:$F$400,8) -> 0 | D17: =C17-B17 -> 0
A18: Phone Bill | B18: 0 | C18: =SUMIFS(Transactions!$E$4:$E$400,Transactions!$C$4:$C$400,$A18,Transactions!$F$4:$F$400,8) -> 0 | D18: =C18-B18 -> 0
A19: Internet | B19: 0 | C19: =SUMIFS(Transactions!$E$4:$E$400,Transactions!$C$4:$C$400,$A19,Transactions!$F$4:$F$400,8) -> 0 | D19: =C19-B19 -> 0
A20: Subscriptions | B20: 0 | C20: =SUMIFS(Transactions!$E$4:$E$400,Transactions!$C$4:$C$400,$A20,Transactions!$F$4:$F$400,8) -> 0 | D20: =C20-B20 -> 0
A21: Car Payment | B21: 0 | C21: =SUMIFS(Transactions!$E$4:$E$400,Transactions!$C$4:$C$400,$A21,Transactions!$F$4:$F$400,8) -> 0 | D21: =C21-B21 -> 0
A22: Loan Payments | B22: 0 | C22: =SUMIFS(Transactions!$E$4:$E$400,Transactions!$C$4:$C$400,$A22,Transactions!$F$4:$F$400,8) -> 0 | D22: =C22-B22 -> 0
A23: Total Fixed Expenses | B23: =SUM(B15:B22) -> 0 | C23: =SUM(C15:C22) -> 0 | D23: =SUM(D15:D22) -> 0
A25: VARIABLE EXPENSES
A26: Groceries | B26: 0 | C26: =SUMIFS(Transactions!$E$4:$E$400,Transactions!$C$4:$C$400,$A26,Transactions!$F$4:$F$400,8) -> 0 | D26: =C26-B26 -> 0
A27: Dining Out | B27: 0 | C27: =SUMIFS(Transactions!$E$4:$E$400,Transactions!$C$4:$C$400,$A27,Transactions!$F$4:$F$400,8) -> 0 | D27: =C27-B27 -> 0
A28: Transportation / Gas | B28: 0 | C28: =SUMIFS(Transactions!$E$4:$E$400,Transactions!$C$4:$C$400,$A28,Transactions!$F$4:$F$400,8) -> 0 | D28: =C28-B28 -> 0
A29: Entertainment | B29: 0 | C29: =SUMIFS(Transactions!$E$4:$E$400,Transactions!$C$4:$C$400,$A29,Transactions!$F$4:$F$400,8) -> 0 | D29: =C29-B29 -> 0
A30: Shopping | B30: 0 | C30: =SUMIFS(Transactions!$E$4:$E$400,Transactions!$C$4:$C$400,$A30,Transactions!$F$4:$F$400,8) -> 0 | D30: =C30-B30 -> 0
A31: Personal Care | B31: 0 | C31: =SUMIFS(Transactions!$E$4:$E$400,Transactions!$C$4:$C$400,$A31,Transactions!$F$4:$F$400,8) -> 0 | D31: =C31-B31 -> 0
A32: Health / Medical | B32: 0 | C32: =SUMIFS(Transactions!$E$4:$E$400,Transactions!$C$4:$C$400,$A32,Transactions!$F$4:$F$400,8) -> 0 | D32: =C32-B32 -> 0
A33: Pet Care | B33: 0 | C33: =SUMIFS(Transactions!$E$4:$E$400,Transactions!$C$4:$C$400,$A33,Transactions!$F$4:$F$400,8) -> 0 | D33: =C33-B33 -> 0
A34: Childcare | B34: 0 | C34: =SUMIFS(Transactions!$E$4:$E$400,Transactions!$C$4:$C$400,$A34,Transactions!$F$4:$F$400,8) -> 0 | D34: =C34-B34 -> 0
A35: Gifts & Donations | B35: 0 | C35: =SUMIFS(Transactions!$E$4:$E$400,Transactions!$C$4:$C$400,$A35,Transactions!$F$4:$F$400,8) -> 0 | D35: =C35-B35 -> 0
A36: Travel | B36: 0 | C36: =SUMIFS(Transactions!$E$4:$E$400,Transactions!$C$4:$C$400,$A36,Transactions!$F$4:$F$400,8) -> 0 | D36: =C36-B36 -> 0
A37: Miscellaneous | B37: 0 | C37: =SUMIFS(Transactions!$E$4:$E$400,Transactions!$C$4:$C$400,$A37,Transactions!$F$4:$F$400,8) -> 0 | D37: =C37-B37 -> 0
A38: Total Variable Expenses | B38: =SUM(B26:B37) -> 0 | C38: =SUM(C26:C37) -> 0 | D38: =SUM(D26:D37) -> 0
A40: SAVINGS & DEBT
A41: Emergency Fund | B41: 0 | C41: =SUMIFS(Transactions!$E$4:$E$400,Transactions!$C$4:$C$400,$A41,Transactions!$F$4:$F$400,8) -> 0 | D41: =C41-B41 -> 0
A42: Retirement Savings | B42: 0 | C42: =SUMIFS(Transactions!$E$4:$E$400,Transactions!$C$4:$C$400,$A42,Transactions!$F$4:$F$400,8) -> 0 | D42: =C42-B42 -> 0
A43: Investment Contributions | B43: 0 | C43: =SUMIFS(Transactions!$E$4:$E$400,Transactions!$C$4:$C$400,$A43,Transactions!$F$4:$F$400,8) -> 0 | D43: =C43-B43 -> 0
A44: Debt Payoff | B44: 0 | C44: =SUMIFS(Transactions!$E$4:$E$400,Transactions!$C$4:$C$400,$A44,Transactions!$F$4:$F$400,8) -> 0 | D44: =C44-B44 -> 0
...

Sheet Sep
A1: ="SEPTEMBER"&" "&Welcome!$B$7&" BUDGET" -> SEPTEMBER 2026 BUDGET
A2: Plan it in BUDGETED, then let ACTUAL fill in from your Transactions log.
A4: CATEGORY | B4: BUDGETED | C4: ACTUAL | D4: VARIANCE
A5: INCOME
A6: Salary | B6: 0 | C6: =SUMIFS(Transactions!$E$4:$E$400,Transactions!$C$4:$C$400,$A6,Transactions!$F$4:$F$400,9) -> 0 | D6: =C6-B6 -> 0
A7: Freelance / Side Hustle | B7: 0 | C7: =SUMIFS(Transactions!$E$4:$E$400,Transactions!$C$4:$C$400,$A7,Transactions!$F$4:$F$400,9) -> 0 | D7: =C7-B7 -> 0
A8: Bonus | B8: 0 | C8: =SUMIFS(Transactions!$E$4:$E$400,Transactions!$C$4:$C$400,$A8,Transactions!$F$4:$F$400,9) -> 0 | D8: =C8-B8 -> 0
A9: Investment Income | B9: 0 | C9: =SUMIFS(Transactions!$E$4:$E$400,Transactions!$C$4:$C$400,$A9,Transactions!$F$4:$F$400,9) -> 0 | D9: =C9-B9 -> 0
A10: Gifts Received | B10: 0 | C10: =SUMIFS(Transactions!$E$4:$E$400,Transactions!$C$4:$C$400,$A10,Transactions!$F$4:$F$400,9) -> 0 | D10: =C10-B10 -> 0
A11: Other Income | B11: 0 | C11: =SUMIFS(Transactions!$E$4:$E$400,Transactions!$C$4:$C$400,$A11,Transactions!$F$4:$F$400,9) -> 0 | D11: =C11-B11 -> 0
A12: Total Income | B12: =SUM(B6:B11) -> 0 | C12: =SUM(C6:C11) -> 0 | D12: =SUM(D6:D11) -> 0
A14: FIXED EXPENSES
A15: Rent / Mortgage | B15: 0 | C15: =SUMIFS(Transactions!$E$4:$E$400,Transactions!$C$4:$C$400,$A15,Transactions!$F$4:$F$400,9) -> 0 | D15: =C15-B15 -> 0
A16: Utilities | B16: 0 | C16: =SUMIFS(Transactions!$E$4:$E$400,Transactions!$C$4:$C$400,$A16,Transactions!$F$4:$F$400,9) -> 0 | D16: =C16-B16 -> 0
A17: Insurance | B17: 0 | C17: =SUMIFS(Transactions!$E$4:$E$400,Transactions!$C$4:$C$400,$A17,Transactions!$F$4:$F$400,9) -> 0 | D17: =C17-B17 -> 0
A18: Phone Bill | B18: 0 | C18: =SUMIFS(Transactions!$E$4:$E$400,Transactions!$C$4:$C$400,$A18,Transactions!$F$4:$F$400,9) -> 0 | D18: =C18-B18 -> 0
A19: Internet | B19: 0 | C19: =SUMIFS(Transactions!$E$4:$E$400,Transactions!$C$4:$C$400,$A19,Transactions!$F$4:$F$400,9) -> 0 | D19: =C19-B19 -> 0
A20: Subscriptions | B20: 0 | C20: =SUMIFS(Transactions!$E$4:$E$400,Transactions!$C$4:$C$400,$A20,Transactions!$F$4:$F$400,9) -> 0 | D20: =C20-B20 -> 0
A21: Car Payment | B21: 0 | C21: =SUMIFS(Transactions!$E$4:$E$400,Transactions!$C$4:$C$400,$A21,Transactions!$F$4:$F$400,9) -> 0 | D21: =C21-B21 -> 0
A22: Loan Payments | B22: 0 | C22: =SUMIFS(Transactions!$E$4:$E$400,Transactions!$C$4:$C$400,$A22,Transactions!$F$4:$F$400,9) -> 0 | D22: =C22-B22 -> 0
A23: Total Fixed Expenses | B23: =SUM(B15:B22) -> 0 | C23: =SUM(C15:C22) -> 0 | D23: =SUM(D15:D22) -> 0
A25: VARIABLE EXPENSES
A26: Groceries | B26: 0 | C26: =SUMIFS(Transactions!$E$4:$E$400,Transactions!$C$4:$C$400,$A26,Transactions!$F$4:$F$400,9) -> 0 | D26: =C26-B26 -> 0
A27: Dining Out | B27: 0 | C27: =SUMIFS(Transactions!$E$4:$E$400,Transactions!$C$4:$C$400,$A27,Transactions!$F$4:$F$400,9) -> 0 | D27: =C27-B27 -> 0
A28: Transportation / Gas | B28: 0 | C28: =SUMIFS(Transactions!$E$4:$E$400,Transactions!$C$4:$C$400,$A28,Transactions!$F$4:$F$400,9) -> 0 | D28: =C28-B28 -> 0
A29: Entertainment | B29: 0 | C29: =SUMIFS(Transactions!$E$4:$E$400,Transactions!$C$4:$C$400,$A29,Transactions!$F$4:$F$400,9) -> 0 | D29: =C29-B29 -> 0
A30: Shopping | B30: 0 | C30: =SUMIFS(Transactions!$E$4:$E$400,Transactions!$C$4:$C$400,$A30,Transactions!$F$4:$F$400,9) -> 0 | D30: =C30-B30 -> 0
A31: Personal Care | B31: 0 | C31: =SUMIFS(Transactions!$E$4:$E$400,Transactions!$C$4:$C$400,$A31,Transactions!$F$4:$F$400,9) -> 0 | D31: =C31-B31 -> 0
A32: Health / Medical | B32: 0 | C32: =SUMIFS(Transactions!$E$4:$E$400,Transactions!$C$4:$C$400,$A32,Transactions!$F$4:$F$400,9) -> 0 | D32: =C32-B32 -> 0
A33: Pet Care | B33: 0 | C33: =SUMIFS(Transactions!$E$4:$E$400,Transactions!$C$4:$C$400,$A33,Transactions!$F$4:$F$400,9) -> 0 | D33: =C33-B33 -> 0
A34: Childcare | B34: 0 | C34: =SUMIFS(Transactions!$E$4:$E$400,Transactions!$C$4:$C$400,$A34,Transactions!$F$4:$F$400,9) -> 0 | D34: =C34-B34 -> 0
A35: Gifts & Donations | B35: 0 | C35: =SUMIFS(Transactions!$E$4:$E$400,Transactions!$C$4:$C$400,$A35,Transactions!$F$4:$F$400,9) -> 0 | D35: =C35-B35 -> 0
A36: Travel | B36: 0 | C36: =SUMIFS(Transactions!$E$4:$E$400,Transactions!$C$4:$C$400,$A36,Transactions!$F$4:$F$400,9) -> 0 | D36: =C36-B36 -> 0
A37: Miscellaneous | B37: 0 | C37: =SUMIFS(Transactions!$E$4:$E$400,Transactions!$C$4:$C$400,$A37,Transactions!$F$4:$F$400,9) -> 0 | D37: =C37-B37 -> 0
A38: Total Variable Expenses | B38: =SUM(B26:B37) -> 0 | C38: =SUM(C26:C37) -> 0 | D38: =SUM(D26:D37) -> 0
A40: SAVINGS & DEBT
A41: Emergency Fund | B41: 0 | C41: =SUMIFS(Transactions!$E$4:$E$400,Transactions!$C$4:$C$400,$A41,Transactions!$F$4:$F$400,9) -> 0 | D41: =C41-B41 -> 0
A42: Retirement Savings | B42: 0 | C42: =SUMIFS(Transactions!$E$4:$E$400,Transactions!$C$4:$C$400,$A42,Transactions!$F$4:$F$400,9) -> 0 | D42: =C42-B42 -> 0
A43: Investment Contributions | B43: 0 | C43: =SUMIFS(Transactions!$E$4:$E$400,Transactions!$C$4:$C$400,$A43,Transactions!$F$4:$F$400,9) -> 0 | D43: =C43-B43 -> 0
A44: Debt Payoff | B44: 0 | C44: =SUMIFS(Transactions!$E$4:$E$400,Transactions!$C$4:$C$400,$A44,Transactions!$F$4:$F$400,9) -> 0 | D44: =C44-B44 -> 0
...

Sheet Oct
A1: ="OCTOBER"&" "&Welcome!$B$7&" BUDGET" -> OCTOBER 2026 BUDGET
A2: Plan it in BUDGETED, then let ACTUAL fill in from your Transactions log.
A4: CATEGORY | B4: BUDGETED | C4: ACTUAL | D4: VARIANCE
A5: INCOME
A6: Salary | B6: 0 | C6: =SUMIFS(Transactions!$E$4:$E$400,Transactions!$C$4:$C$400,$A6,Transactions!$F$4:$F$400,10) -> 0 | D6: =C6-B6 -> 0
A7: Freelance / Side Hustle | B7: 0 | C7: =SUMIFS(Transactions!$E$4:$E$400,Transactions!$C$4:$C$400,$A7,Transactions!$F$4:$F$400,10) -> 0 | D7: =C7-B7 -> 0
A8: Bonus | B8: 0 | C8: =SUMIFS(Transactions!$E$4:$E$400,Transactions!$C$4:$C$400,$A8,Transactions!$F$4:$F$400,10) -> 0 | D8: =C8-B8 -> 0
A9: Investment Income | B9: 0 | C9: =SUMIFS(Transactions!$E$4:$E$400,Transactions!$C$4:$C$400,$A9,Transactions!$F$4:$F$400,10) -> 0 | D9: =C9-B9 -> 0
A10: Gifts Received | B10: 0 | C10: =SUMIFS(Transactions!$E$4:$E$400,Transactions!$C$4:$C$400,$A10,Transactions!$F$4:$F$400,10) -> 0 | D10: =C10-B10 -> 0
A11: Other Income | B11: 0 | C11: =SUMIFS(Transactions!$E$4:$E$400,Transactions!$C$4:$C$400,$A11,Transactions!$F$4:$F$400,10) -> 0 | D11: =C11-B11 -> 0
A12: Total Income | B12: =SUM(B6:B11) -> 0 | C12: =SUM(C6:C11) -> 0 | D12: =SUM(D6:D11) -> 0
A14: FIXED EXPENSES
A15: Rent / Mortgage | B15: 0 | C15: =SUMIFS(Transactions!$E$4:$E$400,Transactions!$C$4:$C$400,$A15,Transactions!$F$4:$F$400,10) -> 0 | D15: =C15-B15 -> 0
A16: Utilities | B16: 0 | C16: =SUMIFS(Transactions!$E$4:$E$400,Transactions!$C$4:$C$400,$A16,Transactions!$F$4:$F$400,10) -> 0 | D16: =C16-B16 -> 0
A17: Insurance | B17: 0 | C17: =SUMIFS(Transactions!$E$4:$E$400,Transactions!$C$4:$C$400,$A17,Transactions!$F$4:$F$400,10) -> 0 | D17: =C17-B17 -> 0
A18: Phone Bill | B18: 0 | C18: =SUMIFS(Transactions!$E$4:$E$400,Transactions!$C$4:$C$400,$A18,Transactions!$F$4:$F$400,10) -> 0 | D18: =C18-B18 -> 0
A19: Internet | B19: 0 | C19: =SUMIFS(Transactions!$E$4:$E$400,Transactions!$C$4:$C$400,$A19,Transactions!$F$4:$F$400,10) -> 0 | D19: =C19-B19 -> 0
A20: Subscriptions | B20: 0 | C20: =SUMIFS(Transactions!$E$4:$E$400,Transactions!$C$4:$C$400,$A20,Transactions!$F$4:$F$400,10) -> 0 | D20: =C20-B20 -> 0
A21: Car Payment | B21: 0 | C21: =SUMIFS(Transactions!$E$4:$E$400,Transactions!$C$4:$C$400,$A21,Transactions!$F$4:$F$400,10) -> 0 | D21: =C21-B21 -> 0
A22: Loan Payments | B22: 0 | C22: =SUMIFS(Transactions!$E$4:$E$400,Transactions!$C$4:$C$400,$A22,Transactions!$F$4:$F$400,10) -> 0 | D22: =C22-B22 -> 0
A23: Total Fixed Expenses | B23: =SUM(B15:B22) -> 0 | C23: =SUM(C15:C22) -> 0 | D23: =SUM(D15:D22) -> 0
A25: VARIABLE EXPENSES
A26: Groceries | B26: 0 | C26: =SUMIFS(Transactions!$E$4:$E$400,Transactions!$C$4:$C$400,$A26,Transactions!$F$4:$F$400,10) -> 0 | D26: =C26-B26 -> 0
A27: Dining Out | B27: 0 | C27: =SUMIFS(Transactions!$E$4:$E$400,Transactions!$C$4:$C$400,$A27,Transactions!$F$4:$F$400,10) -> 0 | D27: =C27-B27 -> 0
A28: Transportation / Gas | B28: 0 | C28: =SUMIFS(Transactions!$E$4:$E$400,Transactions!$C$4:$C$400,$A28,Transactions!$F$4:$F$400,10) -> 0 | D28: =C28-B28 -> 0
A29: Entertainment | B29: 0 | C29: =SUMIFS(Transactions!$E$4:$E$400,Transactions!$C$4:$C$400,$A29,Transactions!$F$4:$F$400,10) -> 0 | D29: =C29-B29 -> 0
A30: Shopping | B30: 0 | C30: =SUMIFS(Transactions!$E$4:$E$400,Transactions!$C$4:$C$400,$A30,Transactions!$F$4:$F$400,10) -> 0 | D30: =C30-B30 -> 0
A31: Personal Care | B31: 0 | C31: =SUMIFS(Transactions!$E$4:$E$400,Transactions!$C$4:$C$400,$A31,Transactions!$F$4:$F$400,10) -> 0 | D31: =C31-B31 -> 0
A32: Health / Medical | B32: 0 | C32: =SUMIFS(Transactions!$E$4:$E$400,Transactions!$C$4:$C$400,$A32,Transactions!$F$4:$F$400,10) -> 0 | D32: =C32-B32 -> 0
A33: Pet Care | B33: 0 | C33: =SUMIFS(Transactions!$E$4:$E$400,Transactions!$C$4:$C$400,$A33,Transactions!$F$4:$F$400,10) -> 0 | D33: =C33-B33 -> 0
A34: Childcare | B34: 0 | C34: =SUMIFS(Transactions!$E$4:$E$400,Transactions!$C$4:$C$400,$A34,Transactions!$F$4:$F$400,10) -> 0 | D34: =C34-B34 -> 0
A35: Gifts & Donations | B35: 0 | C35: =SUMIFS(Transactions!$E$4:$E$400,Transactions!$C$4:$C$400,$A35,Transactions!$F$4:$F$400,10) -> 0 | D35: =C35-B35 -> 0
A36: Travel | B36: 0 | C36: =SUMIFS(Transactions!$E$4:$E$400,Transactions!$C$4:$C$400,$A36,Transactions!$F$4:$F$400,10) -> 0 | D36: =C36-B36 -> 0
A37: Miscellaneous | B37: 0 | C37: =SUMIFS(Transactions!$E$4:$E$400,Transactions!$C$4:$C$400,$A37,Transactions!$F$4:$F$400,10) -> 0 | D37: =C37-B37 -> 0
A38: Total Variable Expenses | B38: =SUM(B26:B37) -> 0 | C38: =SUM(C26:C37) -> 0 | D38: =SUM(D26:D37) -> 0
A40: SAVINGS & DEBT
A41: Emergency Fund | B41: 0 | C41: =SUMIFS(Transactions!$E$4:$E$400,Transactions!$C$4:$C$400,$A41,Transactions!$F$4:$F$400,10) -> 0 | D41: =C41-B41 -> 0
A42: Retirement Savings | B42: 0 | C42: =SUMIFS(Transactions!$E$4:$E$400,Transactions!$C$4:$C$400,$A42,Transactions!$F$4:$F$400,10) -> 0 | D42: =C42-B42 -> 0
A43: Investment Contributions | B43: 0 | C43: =SUMIFS(Transactions!$E$4:$E$400,Transactions!$C$4:$C$400,$A43,Transactions!$F$4:$F$400,10) -> 0 | D43: =C43-B43 -> 0
A44: Debt Payoff | B44: 0 | C44: =SUMIFS(Transactions!$E$4:$E$400,Transactions!$C$4:$C$400,$A44,Transactions!$F$4:$F$400,10) -> 0 | D44: =C44-B44 -> 0
...

Sheet Nov
A1: ="NOVEMBER"&" "&Welcome!$B$7&" BUDGET" -> NOVEMBER 2026 BUDGET
A2: Plan it in BUDGETED, then let ACTUAL fill in from your Transactions log.
A4: CATEGORY | B4: BUDGETED | C4: ACTUAL | D4: VARIANCE
A5: INCOME
A6: Salary | B6: 0 | C6: =SUMIFS(Transactions!$E$4:$E$400,Transactions!$C$4:$C$400,$A6,Transactions!$F$4:$F$400,11) -> 0 | D6: =C6-B6 -> 0
A7: Freelance / Side Hustle | B7: 0 | C7: =SUMIFS(Transactions!$E$4:$E$400,Transactions!$C$4:$C$400,$A7,Transactions!$F$4:$F$400,11) -> 0 | D7: =C7-B7 -> 0
A8: Bonus | B8: 0 | C8: =SUMIFS(Transactions!$E$4:$E$400,Transactions!$C$4:$C$400,$A8,Transactions!$F$4:$F$400,11) -> 0 | D8: =C8-B8 -> 0
A9: Investment Income | B9: 0 | C9: =SUMIFS(Transactions!$E$4:$E$400,Transactions!$C$4:$C$400,$A9,Transactions!$F$4:$F$400,11) -> 0 | D9: =C9-B9 -> 0
A10: Gifts Received | B10: 0 | C10: =SUMIFS(Transactions!$E$4:$E$400,Transactions!$C$4:$C$400,$A10,Transactions!$F$4:$F$400,11) -> 0 | D10: =C10-B10 -> 0
A11: Other Income | B11: 0 | C11: =SUMIFS(Transactions!$E$4:$E$400,Transactions!$C$4:$C$400,$A11,Transactions!$F$4:$F$400,11) -> 0 | D11: =C11-B11 -> 0
A12: Total Income | B12: =SUM(B6:B11) -> 0 | C12: =SUM(C6:C11) -> 0 | D12: =SUM(D6:D11) -> 0
A14: FIXED EXPENSES
A15: Rent / Mortgage | B15: 0 | C15: =SUMIFS(Transactions!$E$4:$E$400,Transactions!$C$4:$C$400,$A15,Transactions!$F$4:$F$400,11) -> 0 | D15: =C15-B15 -> 0
A16: Utilities | B16: 0 | C16: =SUMIFS(Transactions!$E$4:$E$400,Transactions!$C$4:$C$400,$A16,Transactions!$F$4:$F$400,11) -> 0 | D16: =C16-B16 -> 0
A17: Insurance | B17: 0 | C17: =SUMIFS(Transactions!$E$4:$E$400,Transactions!$C$4:$C$400,$A17,Transactions!$F$4:$F$400,11) -> 0 | D17: =C17-B17 -> 0
A18: Phone Bill | B18: 0 | C18: =SUMIFS(Transactions!$E$4:$E$400,Transactions!$C$4:$C$400,$A18,Transactions!$F$4:$F$400,11) -> 0 | D18: =C18-B18 -> 0
A19: Internet | B19: 0 | C19: =SUMIFS(Transactions!$E$4:$E$400,Transactions!$C$4:$C$400,$A19,Transactions!$F$4:$F$400,11) -> 0 | D19: =C19-B19 -> 0
A20: Subscriptions | B20: 0 | C20: =SUMIFS(Transactions!$E$4:$E$400,Transactions!$C$4:$C$400,$A20,Transactions!$F$4:$F$400,11) -> 0 | D20: =C20-B20 -> 0
A21: Car Payment | B21: 0 | C21: =SUMIFS(Transactions!$E$4:$E$400,Transactions!$C$4:$C$400,$A21,Transactions!$F$4:$F$400,11) -> 0 | D21: =C21-B21 -> 0
A22: Loan Payments | B22: 0 | C22: =SUMIFS(Transactions!$E$4:$E$400,Transactions!$C$4:$C$400,$A22,Transactions!$F$4:$F$400,11) -> 0 | D22: =C22-B22 -> 0
A23: Total Fixed Expenses | B23: =SUM(B15:B22) -> 0 | C23: =SUM(C15:C22) -> 0 | D23: =SUM(D15:D22) -> 0
A25: VARIABLE EXPENSES
A26: Groceries | B26: 0 | C26: =SUMIFS(Transactions!$E$4:$E$400,Transactions!$C$4:$C$400,$A26,Transactions!$F$4:$F$400,11) -> 0 | D26: =C26-B26 -> 0
A27: Dining Out | B27: 0 | C27: =SUMIFS(Transactions!$E$4:$E$400,Transactions!$C$4:$C$400,$A27,Transactions!$F$4:$F$400,11) -> 0 | D27: =C27-B27 -> 0
A28: Transportation / Gas | B28: 0 | C28: =SUMIFS(Transactions!$E$4:$E$400,Transactions!$C$4:$C$400,$A28,Transactions!$F$4:$F$400,11) -> 0 | D28: =C28-B28 -> 0
A29: Entertainment | B29: 0 | C29: =SUMIFS(Transactions!$E$4:$E$400,Transactions!$C$4:$C$400,$A29,Transactions!$F$4:$F$400,11) -> 0 | D29: =C29-B29 -> 0
A30: Shopping | B30: 0 | C30: =SUMIFS(Transactions!$E$4:$E$400,Transactions!$C$4:$C$400,$A30,Transactions!$F$4:$F$400,11) -> 0 | D30: =C30-B30 -> 0
A31: Personal Care | B31: 0 | C31: =SUMIFS(Transactions!$E$4:$E$400,Transactions!$C$4:$C$400,$A31,Transactions!$F$4:$F$400,11) -> 0 | D31: =C31-B31 -> 0
A32: Health / Medical | B32: 0 | C32: =SUMIFS(Transactions!$E$4:$E$400,Transactions!$C$4:$C$400,$A32,Transactions!$F$4:$F$400,11) -> 0 | D32: =C32-B32 -> 0
A33: Pet Care | B33: 0 | C33: =SUMIFS(Transactions!$E$4:$E$400,Transactions!$C$4:$C$400,$A33,Transactions!$F$4:$F$400,11) -> 0 | D33: =C33-B33 -> 0
A34: Childcare | B34: 0 | C34: =SUMIFS(Transactions!$E$4:$E$400,Transactions!$C$4:$C$400,$A34,Transactions!$F$4:$F$400,11) -> 0 | D34: =C34-B34 -> 0
A35: Gifts & Donations | B35: 0 | C35: =SUMIFS(Transactions!$E$4:$E$400,Transactions!$C$4:$C$400,$A35,Transactions!$F$4:$F$400,11) -> 0 | D35: =C35-B35 -> 0
A36: Travel | B36: 0 | C36: =SUMIFS(Transactions!$E$4:$E$400,Transactions!$C$4:$C$400,$A36,Transactions!$F$4:$F$400,11) -> 0 | D36: =C36-B36 -> 0
A37: Miscellaneous | B37: 0 | C37: =SUMIFS(Transactions!$E$4:$E$400,Transactions!$C$4:$C$400,$A37,Transactions!$F$4:$F$400,11) -> 0 | D37: =C37-B37 -> 0
A38: Total Variable Expenses | B38: =SUM(B26:B37) -> 0 | C38: =SUM(C26:C37) -> 0 | D38: =SUM(D26:D37) -> 0
A40: SAVINGS & DEBT
A41: Emergency Fund | B41: 0 | C41: =SUMIFS(Transactions!$E$4:$E$400,Transactions!$C$4:$C$400,$A41,Transactions!$F$4:$F$400,11) -> 0 | D41: =C41-B41 -> 0
A42: Retirement Savings | B42: 0 | C42: =SUMIFS(Transactions!$E$4:$E$400,Transactions!$C$4:$C$400,$A42,Transactions!$F$4:$F$400,11) -> 0 | D42: =C42-B42 -> 0
A43: Investment Contributions | B43: 0 | C43: =SUMIFS(Transactions!$E$4:$E$400,Transactions!$C$4:$C$400,$A43,Transactions!$F$4:$F$400,11) -> 0 | D43: =C43-B43 -> 0
A44: Debt Payoff | B44: 0 | C44: =SUMIFS(Transactions!$E$4:$E$400,Transactions!$C$4:$C$400,$A44,Transactions!$F$4:$F$400,11) -> 0 | D44: =C44-B44 -> 0
...

Sheet Dec
A1: ="DECEMBER"&" "&Welcome!$B$7&" BUDGET" -> DECEMBER 2026 BUDGET
A2: Plan it in BUDGETED, then let ACTUAL fill in from your Transactions log.
A4: CATEGORY | B4: BUDGETED | C4: ACTUAL | D4: VARIANCE
A5: INCOME
A6: Salary | B6: 0 | C6: =SUMIFS(Transactions!$E$4:$E$400,Transactions!$C$4:$C$400,$A6,Transactions!$F$4:$F$400,12) -> 0 | D6: =C6-B6 -> 0
